<robot name="collision_table">
    <link concave="yes" name="baseLink">
        <contact>
            <lateral_friction value="0.5"/>
            <rolling_friction value="0.0"/>
            <contact_cfm value="0.0"/>
            <contact_erp value="1.0"/>
        </contact>
        <collision concave="yes">
            <geometry>
                <mesh filename="CollisionTable.obj" scale=".001 .001 .001"/>
            </geometry>
            <origin rpy="1.5707963 0 0" xyz="-.6096 .365125 0"/>
        </collision>
        <visual>
            <origin rpy="1.5707963 0 0" xyz="-.6096 .365125 0"/>
            <geometry>
                <mesh filename="CollisionTable.obj" scale=".001 .001 .001"/>
            </geometry>
            <material name="red">
                <color rgba="1 0 0 1"/>
            </material>
        </visual>
        <inertial>
            <mass value="0"/>
            <inertia ixx="0" ixy="0" ixz="0" iyy="0" iyz="0" izz="0"/>
            <origin rpy="1.5707963 0 0" xyz="-.6096 .365125 0"/>
        </inertial>
    </link>
    <link name="goalieBlock1">
        <collision>
            <origin rpy="-1.5707963 0 0" xyz="-.03215 0 0"/>
            <geometry>
                <box size=".0625 .03125 .125"/>
            </geometry>
        </collision>
        <visual>
            <origin rpy="-1.5707963 0 0" xyz="-.03125 0 0"/>
            <geometry>
                <box size=".0625 .03125 .125"/>
            </geometry>
            <material name="White">
                <color rgba="1 1 1 1"/>
            </material>
        </visual>
        <inertial>
            <mass value="1"/>
            <inertia ixx="0" ixy="0" ixz="0" iyy="0" iyz="0" izz="0"/>
            <origin rpy="-1.5707963 0 0" xyz="0 0 0"/>
        </inertial>
    </link>
    <link name="goalieBlock2">
        <collision>
            <origin rpy="-1.5707963 0 0" xyz="-.03215 0 0"/>
            <geometry>
                <box size=".0625 .03125 .125"/>
            </geometry>
        </collision>
        <visual>
            <origin rpy="-1.5707963 0 0" xyz="-.03125 0 0"/>
            <geometry>
                <box size=".0625 .03125 .125"/>
            </geometry>
            <material name="Black">
                <color rgba="0.2 0.2 0.2 1"/>
            </material>
        </visual>
        <inertial>
            <mass value="1"/>
            <inertia ixx="0" ixy="0" ixz="0" iyy="0" iyz="0" izz="0"/>
            <origin rpy="-1.5707963 0 0" xyz="0 0 0"/>
        </inertial>
    </link>
    <link name="defenseBlock1">
        <collision>
            <origin rpy="-1.5707963 0 0" xyz="-.03215 0 0"/>
            <geometry>
                <box size=".0625 .03125 .125"/>
            </geometry>
        </collision>
        <visual>
            <origin rpy="-1.5707963 0 0" xyz="-.03125 0 0"/>
            <geometry>
                <box size=".0625 .03125 .125"/>
            </geometry>
            <material name="White"/>
        </visual>
        <inertial>
            <mass value="1"/>
            <inertia ixx="0" ixy="0" ixz="0" iyy="0" iyz="0" izz="0"/>
            <origin rpy="-1.5707963 0 0" xyz="0 0 0"/>
        </inertial>
    </link>
    <link name="defenseBlock2">
        <collision>
            <origin rpy="-1.5707963 0 0" xyz="-.03215 0 0"/>
            <geometry>
                <box size=".0625 .03125 .125"/>
            </geometry>
        </collision>
        <visual>
            <origin rpy="-1.5707963 0 0" xyz="-.03125 0 0"/>
            <geometry>
                <box size=".0625 .03125 .125"/>
            </geometry>
            <material name="Black"/>
        </visual>
        <inertial>
            <mass value="1"/>
            <inertia ixx="0" ixy="0" ixz="0" iyy="0" iyz="0" izz="0"/>
            <origin rpy="-1.5707963 0 0" xyz="0 0 0"/>
        </inertial>
    </link>
    <link name="midfieldBlock1">
        <collision>
            <origin rpy="-1.5707963 0 0" xyz="-.03215 0 0"/>
            <geometry>
                <box size=".0625 .03125 .125"/>
            </geometry>
        </collision>
        <visual>
            <origin rpy="-1.5707963 0 0" xyz="-.03125 0 0"/>
            <geometry>
                <box size=".0625 .03125 .125"/>
            </geometry>
            <material name="White"/>
        </visual>
        <inertial>
            <mass value="1"/>
            <inertia ixx="0" ixy="0" ixz="0" iyy="0" iyz="0" izz="0"/>
            <origin rpy="-1.5707963 0 0" xyz="0 0 0"/>
        </inertial>
    </link>
    <link name="midfieldBlock2">
        <collision>
            <origin rpy="-1.5707963 0 0" xyz="-.03215 0 0"/>
            <geometry>
                <box size=".0625 .03125 .125"/>
            </geometry>
        </collision>
        <visual>
            <origin rpy="-1.5707963 0 0" xyz="-.03125 0 0"/>
            <geometry>
                <box size=".0625 .03125 .125"/>
            </geometry>
            <material name="Black"/>
        </visual>
        <inertial>
            <mass value="1"/>
            <inertia ixx="0" ixy="0" ixz="0" iyy="0" iyz="0" izz="0"/>
            <origin rpy="-1.5707963 0 0" xyz="0 0 0"/>
        </inertial>
    </link>
    <link name="strikerBlock1">
        <collision>
            <origin rpy="-1.5707963 0 0" xyz="-.03215 0 0"/>
            <geometry>
                <box size=".0625 .03125 .125"/>
            </geometry>
        </collision>
        <visual>
            <origin rpy="-1.5707963 0 0" xyz="-.03125 0 0"/>
            <geometry>
                <box size=".0625 .03125 .125"/>
            </geometry>
            <material name="White"/>
        </visual>
        <inertial>
            <mass value="1"/>
            <inertia ixx="0" ixy="0" ixz="0" iyy="0" iyz="0" izz="0"/>
            <origin rpy="-1.5707963 0 0" xyz="0 0 0"/>
        </inertial>
    </link>
    <link name="strikerBlock2">
        <collision>
            <origin rpy="-1.5707963 0 0" xyz="-.03215 0 0"/>
            <geometry>
                <box size=".0625 .03125 .125"/>
            </geometry>
        </collision>
        <visual>
            <origin rpy="-1.5707963 0 0" xyz="-.03125 0 0"/>
            <geometry>
                <box size=".0625 .03125 .125"/>
            </geometry>
            <material name="Black"/>
        </visual>
        <inertial>
            <mass value="1"/>
            <inertia ixx="0" ixy="0" ixz="0" iyy="0" iyz="0" izz="0"/>
            <origin rpy="-1.5707963 0 0" xyz="0 0 0"/>
        </inertial>
    </link>
    <link name="goalieRod1">
        <collision>
            <origin rpy="-1.5707963 0 0" xyz="0 0 0"/>
            <geometry>
                <cylinder radius=".0078613" length="1"/>
            </geometry>
        </collision>
        <visual>
            <origin rpy="-1.5707963 0 0" xyz="0 0 0"/>
            <geometry>
                <mesh filename="GoalieRod.obj" scale=".001 .001 .001"/>
            </geometry>
            <material name="White"/>
        </visual>
        <inertial>
            <mass value="1"/>
            <inertia ixx="0" ixy="0" ixz="0" iyy="0" iyz="0" izz="0"/>
            <origin rpy="-1.5707963 0 0" xyz="0 0 0"/>
        </inertial>
    </link>
    <link name="goalieRod2">
        <collision>
            <origin rpy="-1.5707963 0 0" xyz="0 0 0"/>
            <geometry>
                <cylinder radius=".0078613" length="1"/>
            </geometry>
        </collision>
        <visual>
            <origin rpy="-1.5707963 0 0" xyz="0 0 0"/>
            <geometry>
                <mesh filename="GoalieRod.obj" scale=".001 .001 .001"/>
            </geometry>
            <material name="Black"/>
        </visual>
        <inertial>
            <mass value="1"/>
            <inertia ixx="0" ixy="0" ixz="0" iyy="0" iyz="0" izz="0"/>
            <origin rpy="-1.5707963 0 0" xyz="0 0 0"/>
        </inertial>
    </link>
    <link name="defenseRod1">
        <collision>
            <origin rpy="-1.5707963 0 0" xyz="0 0 0"/>
            <geometry>
                <cylinder radius=".0078613" length="1"/>
            </geometry>
        </collision>
        <visual>
            <origin rpy="-1.5707963 0 0" xyz="0 0 0"/>
            <geometry>
                <mesh filename="DefenseRod.obj" scale=".001 .001 .001"/>
            </geometry>
            <material name="White"/>
        </visual>
        <inertial>
            <mass value="1"/>
            <inertia ixx="0" ixy="0" ixz="0" iyy="0" iyz="0" izz="0"/>
            <origin rpy="-1.5707963 0 0" xyz="0 0 0"/>
        </inertial>
    </link>
    <link name="defenseRod2">
        <collision>
            <origin rpy="-1.5707963 0 0" xyz="0 0 0"/>
            <geometry>
                <cylinder radius=".0078613" length="1"/>
            </geometry>
        </collision>
        <visual>
            <origin rpy="-1.5707963 0 0" xyz="0 0 0"/>
            <geometry>
                <mesh filename="DefenseRod.obj" scale=".001 .001 .001"/>
            </geometry>
            <material name="Black"/>
        </visual>
        <inertial>
            <mass value="1"/>
            <inertia ixx="0" ixy="0" ixz="0" iyy="0" iyz="0" izz="0"/>
            <origin rpy="-1.5707963 0 0" xyz="0 0 0"/>
        </inertial>
    </link>
    <link name="midfieldRod1">
        <collision>
            <origin rpy="-1.5707963 0 0" xyz="0 0 0"/>
            <geometry>
                <cylinder radius=".0078613" length="1"/>
            </geometry>
        </collision>
        <visual>
            <origin rpy="-1.5707963 0 0" xyz="0 0 0"/>
            <geometry>
                <mesh filename="MidfieldRod.obj" scale=".001 .001 .001"/>
            </geometry>
            <material name="White"/>
        </visual>
        <inertial>
            <mass value="1"/>
            <inertia ixx="0" ixy="0" ixz="0" iyy="0" iyz="0" izz="0"/>
            <origin rpy="-1.5707963 0 0" xyz="0 0 0"/>
        </inertial>
    </link>
    <link name="midfieldRod2">
        <collision>
            <origin rpy="-1.5707963 0 0" xyz="0 0 0"/>
            <geometry>
                <cylinder radius=".0078613" length="1"/>
            </geometry>
        </collision>
        <visual>
            <origin rpy="-1.5707963 0 0" xyz="0 0 0"/>
            <geometry>
                <mesh filename="MidfieldRod.obj" scale=".001 .001 .001"/>
            </geometry>
            <material name="Black"/>
        </visual>
        <inertial>
            <mass value="1"/>
            <inertia ixx="0" ixy="0" ixz="0" iyy="0" iyz="0" izz="0"/>
            <origin rpy="-1.5707963 0 0" xyz="0 0 0"/>
        </inertial>
    </link>
    <link name="strikerRod1">
        <collision>
            <origin rpy="-1.5707963 0 0" xyz="0 0 0"/>
            <geometry>
                <cylinder radius=".0078613" length="1"/>
            </geometry>
        </collision>
        <visual>
            <origin rpy="-1.5707963 0 0" xyz="0 0 0"/>
            <geometry>
                <mesh filename="StrikerRod.obj" scale=".001 .001 .001"/>
            </geometry>
            <material name="White"/>
        </visual>
        <inertial>
            <mass value="1"/>
            <inertia ixx="0" ixy="0" ixz="0" iyy="0" iyz="0" izz="0"/>
            <origin rpy="-1.5707963 0 0" xyz="0 0 0"/>
        </inertial>
    </link>
    <link name="strikerRod2">
        <collision>
            <origin rpy="-1.5707963 0 0" xyz="0 0 0"/>
            <geometry>
                <cylinder radius=".0078613" length="1"/>
            </geometry>
        </collision>
        <visual>
            <origin rpy="-1.5707963 0 0" xyz="0 0 0"/>
            <geometry>
                <mesh filename="StrikerRod.obj" scale=".001 .001 .001"/>
            </geometry>
            <material name="Black"/>
        </visual>
        <inertial>
            <mass value="1"/>
            <inertia ixx="0" ixy="0" ixz="0" iyy="0" iyz="0" izz="0"/>
            <origin rpy="-1.5707963 0 0" xyz="0 0 0"/>
        </inertial>
    </link>
    <link name="goaliePlayer11">
        <contact>
            <lateral_friction value="0.5"/>
            <rolling_friction value="0.0"/>
            <contact_cfm value="0.0"/>
            <contact_erp value="1.0"/>
        </contact>
        <collision>
            <origin rpy="1.5707963 0 0" xyz="0 0 -0.0658368"/>
            <geometry>
                <mesh filename="PlayerCollider.obj" scale=".001 .001 .001"/>
            </geometry>
        </collision>
        <visual>
            <origin rpy="1.5707963 0 0" xyz="0 0 -0.0658368"/>
            <geometry>
                <mesh filename="PlayerVisual.obj" scale=".001 .001 .001"/>
            </geometry>
            <material name="White"/>
        </visual>
        <inertial>
            <mass value="1"/>
            <inertia ixx="0" ixy="0" ixz="0" iyy="0" iyz="0" izz="0"/>
            <origin rpy="-1.5707963 0 0" xyz="0 0 0"/>
        </inertial>
    </link>
    <link name="goaliePlayer12">
        <contact>
            <lateral_friction value="0.5"/>
            <rolling_friction value="0.0"/>
            <contact_cfm value="0.0"/>
            <contact_erp value="1.0"/>
        </contact>
        <collision>
            <origin rpy="1.5707963 0 0" xyz="0 0 -0.0658368"/>
            <geometry>
                <mesh filename="PlayerCollider.obj" scale=".001 .001 .001"/>
            </geometry>
        </collision>
        <visual>
            <origin rpy="1.5707963 0 0" xyz="0 0 -0.0658368"/>
            <geometry>
                <mesh filename="PlayerVisual.obj" scale=".001 .001 .001"/>
            </geometry>
            <material name="White"/>
        </visual>
        <inertial>
            <mass value="1"/>
            <inertia ixx="0" ixy="0" ixz="0" iyy="0" iyz="0" izz="0"/>
            <origin rpy="-1.5707963 0 0" xyz="0 0 0"/>
        </inertial>
    </link>
    <link name="goaliePlayer13">
        <contact>
            <lateral_friction value="0.5"/>
            <rolling_friction value="0.0"/>
            <contact_cfm value="0.0"/>
            <contact_erp value="1.0"/>
        </contact>
        <collision>
            <origin rpy="1.5707963 0 0" xyz="0 0 -0.0658368"/>
            <geometry>
                <mesh filename="PlayerCollider.obj" scale=".001 .001 .001"/>
            </geometry>
        </collision>
        <visual>
            <origin rpy="1.5707963 0 0" xyz="0 0 -0.0658368"/>
            <geometry>
                <mesh filename="PlayerVisual.obj" scale=".001 .001 .001"/>
            </geometry>
            <material name="White"/>
        </visual>
        <inertial>
            <mass value="1"/>
            <inertia ixx="0" ixy="0" ixz="0" iyy="0" iyz="0" izz="0"/>
            <origin rpy="-1.5707963 0 0" xyz="0 0 0"/>
        </inertial>
    </link>
    <link name="goaliePlayer21">
        <contact>
            <lateral_friction value="0.5"/>
            <rolling_friction value="0.0"/>
            <contact_cfm value="0.0"/>
            <contact_erp value="1.0"/>
        </contact>
        <collision>
            <origin rpy="1.5707963 0 0" xyz="0 0 -0.0658368"/>
            <geometry>
                <mesh filename="PlayerCollider.obj" scale=".001 .001 .001"/>
            </geometry>
        </collision>
        <visual>
            <origin rpy="1.5707963 0 0" xyz="0 0 -0.0658368"/>
            <geometry>
                <mesh filename="PlayerVisual.obj" scale=".001 .001 .001"/>
            </geometry>
            <material name="Black"/>
        </visual>
        <inertial>
            <mass value="1"/>
            <inertia ixx="0" ixy="0" ixz="0" iyy="0" iyz="0" izz="0"/>
            <origin rpy="-1.5707963 0 0" xyz="0 0 0"/>
        </inertial>
    </link>
    <link name="goaliePlayer22">
        <contact>
            <lateral_friction value="0.5"/>
            <rolling_friction value="0.0"/>
            <contact_cfm value="0.0"/>
            <contact_erp value="1.0"/>
        </contact>
        <collision>
            <origin rpy="1.5707963 0 0" xyz="0 0 -0.0658368"/>
            <geometry>
                <mesh filename="PlayerCollider.obj" scale=".001 .001 .001"/>
            </geometry>
        </collision>
        <visual>
            <origin rpy="1.5707963 0 0" xyz="0 0 -0.0658368"/>
            <geometry>
                <mesh filename="PlayerVisual.obj" scale=".001 .001 .001"/>
            </geometry>
            <material name="Black"/>
        </visual>
        <inertial>
            <mass value="1"/>
            <inertia ixx="0" ixy="0" ixz="0" iyy="0" iyz="0" izz="0"/>
            <origin rpy="-1.5707963 0 0" xyz="0 0 0"/>
        </inertial>
    </link>
    <link name="goaliePlayer23">
        <contact>
            <lateral_friction value="0.5"/>
            <rolling_friction value="0.0"/>
            <contact_cfm value="0.0"/>
            <contact_erp value="1.0"/>
        </contact>
        <collision>
            <origin rpy="1.5707963 0 0" xyz="0 0 -0.0658368"/>
            <geometry>
                <mesh filename="PlayerCollider.obj" scale=".001 .001 .001"/>
            </geometry>
        </collision>
        <visual>
            <origin rpy="1.5707963 0 0" xyz="0 0 -0.0658368"/>
            <geometry>
                <mesh filename="PlayerVisual.obj" scale=".001 .001 .001"/>
            </geometry>
            <material name="Black"/>
        </visual>
        <inertial>
            <mass value="1"/>
            <inertia ixx="0" ixy="0" ixz="0" iyy="0" iyz="0" izz="0"/>
            <origin rpy="-1.5707963 0 0" xyz="0 0 0"/>
        </inertial>
    </link>
    <link name="defensePlayer11">
        <contact>
            <lateral_friction value="0.5"/>
            <rolling_friction value="0.0"/>
            <contact_cfm value="0.0"/>
            <contact_erp value="1.0"/>
        </contact>
        <collision>
            <origin rpy="1.5707963 0 0" xyz="0 0 -0.0658368"/>
            <geometry>
                <mesh filename="PlayerCollider.obj" scale=".001 .001 .001"/>
            </geometry>
        </collision>
        <visual>
            <origin rpy="1.5707963 0 0" xyz="0 0 -0.0658368"/>
            <geometry>
                <mesh filename="PlayerVisual.obj" scale=".001 .001 .001"/>
            </geometry>
            <material name="White"/>
        </visual>
        <inertial>
            <mass value="1"/>
            <inertia ixx="0" ixy="0" ixz="0" iyy="0" iyz="0" izz="0"/>
            <origin rpy="-1.5707963 0 0" xyz="0 0 0"/>
        </inertial>
    </link>
    <link name="defensePlayer12">
        <contact>
            <lateral_friction value="0.5"/>
            <rolling_friction value="0.0"/>
            <contact_cfm value="0.0"/>
            <contact_erp value="1.0"/>
        </contact>
        <collision>
            <origin rpy="1.5707963 0 0" xyz="0 0 -0.0658368"/>
            <geometry>
                <mesh filename="PlayerCollider.obj" scale=".001 .001 .001"/>
            </geometry>
        </collision>
        <visual>
            <origin rpy="1.5707963 0 0" xyz="0 0 -0.0658368"/>
            <geometry>
                <mesh filename="PlayerVisual.obj" scale=".001 .001 .001"/>
            </geometry>
            <material name="White"/>
        </visual>
        <inertial>
            <mass value="1"/>
            <inertia ixx="0" ixy="0" ixz="0" iyy="0" iyz="0" izz="0"/>
            <origin rpy="-1.5707963 0 0" xyz="0 0 0"/>
        </inertial>
    </link>
    <link name="defensePlayer21">
        <contact>
            <lateral_friction value="0.5"/>
            <rolling_friction value="0.0"/>
            <contact_cfm value="0.0"/>
            <contact_erp value="1.0"/>
        </contact>
        <collision>
            <origin rpy="1.5707963 0 0" xyz="0 0 -0.0658368"/>
            <geometry>
                <mesh filename="PlayerCollider.obj" scale=".001 .001 .001"/>
            </geometry>
        </collision>
        <visual>
            <origin rpy="1.5707963 0 0" xyz="0 0 -0.0658368"/>
            <geometry>
                <mesh filename="PlayerVisual.obj" scale=".001 .001 .001"/>
            </geometry>
            <material name="Black"/>
        </visual>
        <inertial>
            <mass value="1"/>
            <inertia ixx="0" ixy="0" ixz="0" iyy="0" iyz="0" izz="0"/>
            <origin rpy="-1.5707963 0 0" xyz="0 0 0"/>
        </inertial>
    </link>
    <link name="defensePlayer22">
        <contact>
            <lateral_friction value="0.5"/>
            <rolling_friction value="0.0"/>
            <contact_cfm value="0.0"/>
            <contact_erp value="1.0"/>
        </contact>
        <collision>
            <origin rpy="1.5707963 0 0" xyz="0 0 -0.0658368"/>
            <geometry>
                <mesh filename="PlayerCollider.obj" scale=".001 .001 .001"/>
            </geometry>
        </collision>
        <visual>
            <origin rpy="1.5707963 0 0" xyz="0 0 -0.0658368"/>
            <geometry>
                <mesh filename="PlayerVisual.obj" scale=".001 .001 .001"/>
            </geometry>
            <material name="Black"/>
        </visual>
        <inertial>
            <mass value="1"/>
            <inertia ixx="0" ixy="0" ixz="0" iyy="0" iyz="0" izz="0"/>
            <origin rpy="-1.5707963 0 0" xyz="0 0 0"/>
        </inertial>
    </link>
    <link name="midfieldPlayer11">
        <contact>
            <lateral_friction value="0.5"/>
            <rolling_friction value="0.0"/>
            <contact_cfm value="0.0"/>
            <contact_erp value="1.0"/>
        </contact>
        <collision>
            <origin rpy="1.5707963 0 0" xyz="0 0 -0.0658368"/>
            <geometry>
                <mesh filename="PlayerCollider.obj" scale=".001 .001 .001"/>
            </geometry>
        </collision>
        <visual>
            <origin rpy="1.5707963 0 0" xyz="0 0 -0.0658368"/>
            <geometry>
                <mesh filename="PlayerVisual.obj" scale=".001 .001 .001"/>
            </geometry>
            <material name="White"/>
        </visual>
        <inertial>
            <mass value="1"/>
            <inertia ixx="0" ixy="0" ixz="0" iyy="0" iyz="0" izz="0"/>
            <origin rpy="-1.5707963 0 0" xyz="0 0 0"/>
        </inertial>
    </link>
    <link name="midfieldPlayer12">
        <contact>
            <lateral_friction value="0.5"/>
            <rolling_friction value="0.0"/>
            <contact_cfm value="0.0"/>
            <contact_erp value="1.0"/>
        </contact>
        <collision>
            <origin rpy="1.5707963 0 0" xyz="0 0 -0.0658368"/>
            <geometry>
                <mesh filename="PlayerCollider.obj" scale=".001 .001 .001"/>
            </geometry>
        </collision>
        <visual>
            <origin rpy="1.5707963 0 0" xyz="0 0 -0.0658368"/>
            <geometry>
                <mesh filename="PlayerVisual.obj" scale=".001 .001 .001"/>
            </geometry>
            <material name="White"/>
        </visual>
        <inertial>
            <mass value="1"/>
            <inertia ixx="0" ixy="0" ixz="0" iyy="0" iyz="0" izz="0"/>
            <origin rpy="-1.5707963 0 0" xyz="0 0 0"/>
        </inertial>
    </link>
    <link name="midfieldPlayer13">
        <contact>
            <lateral_friction value="0.5"/>
            <rolling_friction value="0.0"/>
            <contact_cfm value="0.0"/>
            <contact_erp value="1.0"/>
        </contact>
        <collision>
            <origin rpy="1.5707963 0 0" xyz="0 0 -0.0658368"/>
            <geometry>
                <mesh filename="PlayerCollider.obj" scale=".001 .001 .001"/>
            </geometry>
        </collision>
        <visual>
            <origin rpy="1.5707963 0 0" xyz="0 0 -0.0658368"/>
            <geometry>
                <mesh filename="PlayerVisual.obj" scale=".001 .001 .001"/>
            </geometry>
            <material name="White"/>
        </visual>
        <inertial>
            <mass value="1"/>
            <inertia ixx="0" ixy="0" ixz="0" iyy="0" iyz="0" izz="0"/>
            <origin rpy="-1.5707963 0 0" xyz="0 0 0"/>
        </inertial>
    </link>
    <link name="midfieldPlayer14">
        <contact>
            <lateral_friction value="0.5"/>
            <rolling_friction value="0.0"/>
            <contact_cfm value="0.0"/>
            <contact_erp value="1.0"/>
        </contact>
        <collision>
            <origin rpy="1.5707963 0 0" xyz="0 0 -0.0658368"/>
            <geometry>
                <mesh filename="PlayerCollider.obj" scale=".001 .001 .001"/>
            </geometry>
        </collision>
        <visual>
            <origin rpy="1.5707963 0 0" xyz="0 0 -0.0658368"/>
            <geometry>
                <mesh filename="PlayerVisual.obj" scale=".001 .001 .001"/>
            </geometry>
            <material name="White"/>
        </visual>
        <inertial>
            <mass value="1"/>
            <inertia ixx="0" ixy="0" ixz="0" iyy="0" iyz="0" izz="0"/>
            <origin rpy="-1.5707963 0 0" xyz="0 0 0"/>
        </inertial>
    </link>
    <link name="midfieldPlayer15">
        <contact>
            <lateral_friction value="0.5"/>
            <rolling_friction value="0.0"/>
            <contact_cfm value="0.0"/>
            <contact_erp value="1.0"/>
        </contact>
        <collision>
            <origin rpy="1.5707963 0 0" xyz="0 0 -0.0658368"/>
            <geometry>
                <mesh filename="PlayerCollider.obj" scale=".001 .001 .001"/>
            </geometry>
        </collision>
        <visual>
            <origin rpy="1.5707963 0 0" xyz="0 0 -0.0658368"/>
            <geometry>
                <mesh filename="PlayerVisual.obj" scale=".001 .001 .001"/>
            </geometry>
            <material name="White"/>
        </visual>
        <inertial>
            <mass value="1"/>
            <inertia ixx="0" ixy="0" ixz="0" iyy="0" iyz="0" izz="0"/>
            <origin rpy="-1.5707963 0 0" xyz="0 0 0"/>
        </inertial>
    </link>
    <link name="midfieldPlayer21">
        <contact>
            <lateral_friction value="0.5"/>
            <rolling_friction value="0.0"/>
            <contact_cfm value="0.0"/>
            <contact_erp value="1.0"/>
        </contact>
        <collision>
            <origin rpy="1.5707963 0 0" xyz="0 0 -0.0658368"/>
            <geometry>
                <mesh filename="PlayerCollider.obj" scale=".001 .001 .001"/>
            </geometry>
        </collision>
        <visual>
            <origin rpy="1.5707963 0 0" xyz="0 0 -0.0658368"/>
            <geometry>
                <mesh filename="PlayerVisual.obj" scale=".001 .001 .001"/>
            </geometry>
            <material name="Black"/>
        </visual>
        <inertial>
            <mass value="1"/>
            <inertia ixx="0" ixy="0" ixz="0" iyy="0" iyz="0" izz="0"/>
            <origin rpy="-1.5707963 0 0" xyz="0 0 0"/>
        </inertial>
    </link>
    <link name="midfieldPlayer22">
        <contact>
            <lateral_friction value="0.5"/>
            <rolling_friction value="0.0"/>
            <contact_cfm value="0.0"/>
            <contact_erp value="1.0"/>
        </contact>
        <collision>
            <origin rpy="1.5707963 0 0" xyz="0 0 -0.0658368"/>
            <geometry>
                <mesh filename="PlayerCollider.obj" scale=".001 .001 .001"/>
            </geometry>
        </collision>
        <visual>
            <origin rpy="1.5707963 0 0" xyz="0 0 -0.0658368"/>
            <geometry>
                <mesh filename="PlayerVisual.obj" scale=".001 .001 .001"/>
            </geometry>
            <material name="Black"/>
        </visual>
        <inertial>
            <mass value="1"/>
            <inertia ixx="0" ixy="0" ixz="0" iyy="0" iyz="0" izz="0"/>
            <origin rpy="-1.5707963 0 0" xyz="0 0 0"/>
        </inertial>
    </link>
    <link name="midfieldPlayer23">
        <contact>
            <lateral_friction value="0.5"/>
            <rolling_friction value="0.0"/>
            <contact_cfm value="0.0"/>
            <contact_erp value="1.0"/>
        </contact>
        <collision>
            <origin rpy="1.5707963 0 0" xyz="0 0 -0.0658368"/>
            <geometry>
                <mesh filename="PlayerCollider.obj" scale=".001 .001 .001"/>
            </geometry>
        </collision>
        <visual>
            <origin rpy="1.5707963 0 0" xyz="0 0 -0.0658368"/>
            <geometry>
                <mesh filename="PlayerVisual.obj" scale=".001 .001 .001"/>
            </geometry>
            <material name="Black"/>
        </visual>
        <inertial>
            <mass value="1"/>
            <inertia ixx="0" ixy="0" ixz="0" iyy="0" iyz="0" izz="0"/>
            <origin rpy="-1.5707963 0 0" xyz="0 0 0"/>
        </inertial>
    </link>
    <link name="midfieldPlayer24">
        <contact>
            <lateral_friction value="0.5"/>
            <rolling_friction value="0.0"/>
            <contact_cfm value="0.0"/>
            <contact_erp value="1.0"/>
        </contact>
        <collision>
            <origin rpy="1.5707963 0 0" xyz="0 0 -0.0658368"/>
            <geometry>
                <mesh filename="PlayerCollider.obj" scale=".001 .001 .001"/>
            </geometry>
        </collision>
        <visual>
            <origin rpy="1.5707963 0 0" xyz="0 0 -0.0658368"/>
            <geometry>
                <mesh filename="PlayerVisual.obj" scale=".001 .001 .001"/>
            </geometry>
            <material name="Black"/>
        </visual>
        <inertial>
            <mass value="1"/>
            <inertia ixx="0" ixy="0" ixz="0" iyy="0" iyz="0" izz="0"/>
            <origin rpy="-1.5707963 0 0" xyz="0 0 0"/>
        </inertial>
    </link>
    <link name="midfieldPlayer25">
        <contact>
            <lateral_friction value="0.5"/>
            <rolling_friction value="0.0"/>
            <contact_cfm value="0.0"/>
            <contact_erp value="1.0"/>
        </contact>
        <collision>
            <origin rpy="1.5707963 0 0" xyz="0 0 -0.0658368"/>
            <geometry>
                <mesh filename="PlayerCollider.obj" scale=".001 .001 .001"/>
            </geometry>
        </collision>
        <visual>
            <origin rpy="1.5707963 0 0" xyz="0 0 -0.0658368"/>
            <geometry>
                <mesh filename="PlayerVisual.obj" scale=".001 .001 .001"/>
            </geometry>
            <material name="Black"/>
        </visual>
        <inertial>
            <mass value="1"/>
            <inertia ixx="0" ixy="0" ixz="0" iyy="0" iyz="0" izz="0"/>
            <origin rpy="-1.5707963 0 0" xyz="0 0 0"/>
        </inertial>
    </link>
    <link name="strikerPlayer11">
        <contact>
            <lateral_friction value="0.5"/>
            <rolling_friction value="0.0"/>
            <contact_cfm value="0.0"/>
            <contact_erp value="1.0"/>
        </contact>
        <collision>
            <origin rpy="1.5707963 0 0" xyz="0 0 -0.0658368"/>
            <geometry>
                <mesh filename="PlayerCollider.obj" scale=".001 .001 .001"/>
            </geometry>
        </collision>
        <visual>
            <origin rpy="1.5707963 0 0" xyz="0 0 -0.0658368"/>
            <geometry>
                <mesh filename="PlayerVisual.obj" scale=".001 .001 .001"/>
            </geometry>
            <material name="White"/>
        </visual>
        <inertial>
            <mass value="1"/>
            <inertia ixx="0" ixy="0" ixz="0" iyy="0" iyz="0" izz="0"/>
            <origin rpy="-1.5707963 0 0" xyz="0 0 0"/>
        </inertial>
    </link>
    <link name="strikerPlayer12">
        <contact>
            <lateral_friction value="0.5"/>
            <rolling_friction value="0.0"/>
            <contact_cfm value="0.0"/>
            <contact_erp value="1.0"/>
        </contact>
        <collision>
            <origin rpy="1.5707963 0 0" xyz="0 0 -0.0658368"/>
            <geometry>
                <mesh filename="PlayerCollider.obj" scale=".001 .001 .001"/>
            </geometry>
        </collision>
        <visual>
            <origin rpy="1.5707963 0 0" xyz="0 0 -0.0658368"/>
            <geometry>
                <mesh filename="PlayerVisual.obj" scale=".001 .001 .001"/>
            </geometry>
            <material name="White"/>
        </visual>
        <inertial>
            <mass value="1"/>
            <inertia ixx="0" ixy="0" ixz="0" iyy="0" iyz="0" izz="0"/>
            <origin rpy="-1.5707963 0 0" xyz="0 0 0"/>
        </inertial>
    </link>
    <link name="strikerPlayer13">
        <contact>
            <lateral_friction value="0.5"/>
            <rolling_friction value="0.0"/>
            <contact_cfm value="0.0"/>
            <contact_erp value="1.0"/>
        </contact>
        <collision>
            <origin rpy="1.5707963 0 0" xyz="0 0 -0.0658368"/>
            <geometry>
                <mesh filename="PlayerCollider.obj" scale=".001 .001 .001"/>
            </geometry>
        </collision>
        <visual>
            <origin rpy="1.5707963 0 0" xyz="0 0 -0.0658368"/>
            <geometry>
                <mesh filename="PlayerVisual.obj" scale=".001 .001 .001"/>
            </geometry>
            <material name="White"/>
        </visual>
        <inertial>
            <mass value="1"/>
            <inertia ixx="0" ixy="0" ixz="0" iyy="0" iyz="0" izz="0"/>
            <origin rpy="-1.5707963 0 0" xyz="0 0 0"/>
        </inertial>
    </link>
    <link name="strikerPlayer21">
        <contact>
            <lateral_friction value="0.5"/>
            <rolling_friction value="0.0"/>
            <contact_cfm value="0.0"/>
            <contact_erp value="1.0"/>
        </contact>
        <collision>
            <origin rpy="1.5707963 0 0" xyz="0 0 -0.0658368"/>
            <geometry>
                <mesh filename="PlayerCollider.obj" scale=".001 .001 .001"/>
            </geometry>
        </collision>
        <visual>
            <origin rpy="1.5707963 0 0" xyz="0 0 -0.0658368"/>
            <geometry>
                <mesh filename="PlayerVisual.obj" scale=".001 .001 .001"/>
            </geometry>
            <material name="Black"/>
        </visual>
        <inertial>
            <mass value="1"/>
            <inertia ixx="0" ixy="0" ixz="0" iyy="0" iyz="0" izz="0"/>
            <origin rpy="-1.5707963 0 0" xyz="0 0 0"/>
        </inertial>
    </link>
    <link name="strikerPlayer22">
        <contact>
            <lateral_friction value="0.5"/>
            <rolling_friction value="0.0"/>
            <contact_cfm value="0.0"/>
            <contact_erp value="1.0"/>
        </contact>
        <collision>
            <origin rpy="1.5707963 0 0" xyz="0 0 -0.0658368"/>
            <geometry>
                <mesh filename="PlayerCollider.obj" scale=".001 .001 .001"/>
            </geometry>
        </collision>
        <visual>
            <origin rpy="1.5707963 0 0" xyz="0 0 -0.0658368"/>
            <geometry>
                <mesh filename="PlayerVisual.obj" scale=".001 .001 .001"/>
            </geometry>
            <material name="Black"/>
        </visual>
        <inertial>
            <mass value="1"/>
            <inertia ixx="0" ixy="0" ixz="0" iyy="0" iyz="0" izz="0"/>
            <origin rpy="-1.5707963 0 0" xyz="0 0 0"/>
        </inertial>
    </link>
    <link name="strikerPlayer23">
        <contact>
            <lateral_friction value="0.5"/>
            <rolling_friction value="0.0"/>
            <contact_cfm value="0.0"/>
            <contact_erp value="1.0"/>
        </contact>
        <collision>
            <origin rpy="1.5707963 0 0" xyz="0 0 -0.0658368"/>
            <geometry>
                <mesh filename="PlayerCollider.obj" scale=".001 .001 .001"/>
            </geometry>
        </collision>
        <visual>
            <origin rpy="1.5707963 0 0" xyz="0 0 -0.0658368"/>
            <geometry>
                <mesh filename="PlayerVisual.obj" scale=".001 .001 .001"/>
            </geometry>
            <material name="Black"/>
        </visual>
        <inertial>
            <mass value="1"/>
            <inertia ixx="0" ixy="0" ixz="0" iyy="0" iyz="0" izz="0"/>
            <origin rpy="-1.5707963 0 0" xyz="0 0 0"/>
        </inertial>
    </link>
    <joint name="goaliePrismatic1" type="prismatic">
        <origin xyz="0.508 0.687705 0" rpy="0 0 3.14159265"/>
        <parent link="baseLink"/>
        <child link="goalieBlock1"/>
        <limit lower="0" upper=".18161"/>
        <axis xyz="0 1 0"/>
    </joint>
    <joint name="goaliePrismatic2" type="prismatic">
        <origin xyz="-0.508 -0.687705 0" rpy="0 0 0"/>
        <parent link="baseLink"/>
        <child link="goalieBlock2"/>
        <limit lower="0" upper=".18161"/>
        <axis xyz="0 1 0"/>
    </joint>
    <joint name="defensePrismatic1" type="prismatic">
        <origin xyz="0.36195 0.859155 0" rpy="0 0 3.14159265"/>
        <parent link="baseLink"/>
        <child link="defenseBlock1"/>
        <limit lower="0" upper=".35306"/>
        <axis xyz="0 1 0"/>
    </joint>
    <joint name="defensePrismatic2" type="prismatic">
        <origin xyz="-0.36195 -0.859155 0" rpy="0 0 0"/>
        <parent link="baseLink"/>
        <child link="defenseBlock2"/>
        <limit lower="0" upper=".35306"/>
        <axis xyz="0 1 0"/>
    </joint>
    <joint name="midfieldPrismatic1" type="prismatic">
        <origin xyz="0.066675 0.617855 0" rpy="0 0 3.14159265"/>
        <parent link="baseLink"/>
        <child link="midfieldBlock1"/>
        <limit lower="0" upper=".11176"/>
        <axis xyz="0 1 0"/>
    </joint>
    <joint name="midfieldPrismatic2" type="prismatic">
        <origin xyz="-0.066675 -0.617855 0" rpy="0 0 0"/>
        <parent link="baseLink"/>
        <child link="midfieldBlock2"/>
        <limit lower="0" upper=".11176"/>
        <axis xyz="0 1 0"/>
    </joint>
    <joint name="strikerPrismatic1" type="prismatic">
        <origin xyz="-0.2159 0.732155 0" rpy="0 0 3.14159265"/>
        <parent link="baseLink"/>
        <child link="strikerBlock1"/>
        <limit lower="0" upper=".22606"/>
        <axis xyz="0 1 0"/>
    </joint>
    <joint name="strikerPrismatic2" type="prismatic">
        <origin xyz="0.2159 -0.732155 0" rpy="0 0 0"/>
        <parent link="baseLink"/>
        <child link="strikerBlock2"/>
        <limit lower="0" upper=".22606"/>
        <axis xyz="0 1 0"/>
    </joint>
    <joint name="goalieRotation1" type="continuous">
        <origin xyz="0 1.0541 0.098425" rpy="0 0 3.14159265"/>
        <parent link="goalieBlock1"/>
        <child link="goalieRod1"/>
        <axis xyz="0 1 0"/>
    </joint>
    <joint name="goalieRotation2" type="continuous">
        <origin xyz="0 1.0541 0.098425" rpy="0 0 3.14159265"/>
        <parent link="goalieBlock2"/>
        <child link="goalieRod2"/>
        <axis xyz="0 1 0"/>
    </joint>
    <joint name="defenseRotation1" type="continuous">
        <origin xyz="0 1.228725 0.098425" rpy="0 0 3.14152965"/>
        <parent link="defenseBlock1"/>
        <child link="defenseRod1"/>
        <axis xyz="0 1 0"/>
    </joint>
    <joint name="defenseRotation2" type="continuous">
        <origin xyz="0 1.228725 0.098425" rpy="0 0 3.14159265"/>
        <parent link="defenseBlock2"/>
        <child link="defenseRod2"/>
        <axis xyz="0 1 0"/>
    </joint>
    <joint name="midfieldRotation1" type="continuous">
        <origin xyz="0 0.987425 0.098425" rpy="0 0 3.14159265"/>
        <parent link="midfieldBlock1"/>
        <child link="midfieldRod1"/>
        <axis xyz="0 1 0"/>
    </joint>
    <joint name="midfieldRotation2" type="continuous">
        <origin xyz="0 0.987425 0.098425" rpy="0 0 3.14159265"/>
        <parent link="midfieldBlock2"/>
        <child link="midfieldRod2"/>
        <axis xyz="0 1 0"/>
    </joint>
    <joint name="strikerRotation1" type="continuous">
        <origin xyz="0 1.101725 0.098425" rpy="0 0 3.14159265"/>
        <parent link="strikerBlock1"/>
        <child link="strikerRod1"/>
        <axis xyz="0 1 0"/>
    </joint>
    <joint name="strikerRotation2" type="continuous">
        <origin xyz="0 1.101725 0.098425" rpy="0 0 3.14159265"/>
        <parent link="strikerBlock2"/>
        <child link="strikerRod2"/>
        <axis xyz="0 1 0"/>
    </joint>
    <joint name="GP11" type="fixed">
        <origin xyz="0 0.235585 0" rpy="0 0 1.5707963"/>
        <parent link="goalieRod1"/>
        <child link="goaliePlayer11"/>
    </joint>
    <joint name="GP12" type="fixed">
        <origin xyz="0 0.44196 0" rpy="0 0 1.5707963"/>
        <parent link="goalieRod1"/>
        <child link="goaliePlayer12"/>
    </joint>
    <joint name="GP13" type="fixed">
        <origin xyz="0 0.648335 0" rpy="0 0 1.5707963"/>
        <parent link="goalieRod1"/>
        <child link="goaliePlayer13"/>
    </joint>
    <joint name="GP21" type="fixed">
        <origin xyz="0 0.235585 0" rpy="0 0 1.5707963"/>
        <parent link="goalieRod2"/>
        <child link="goaliePlayer21"/>
    </joint>
    <joint name="GP22" type="fixed">
        <origin xyz="0 0.44196 0" rpy="0 0 1.5707963"/>
        <parent link="goalieRod2"/>
        <child link="goaliePlayer22"/>
    </joint>
    <joint name="GP23" type="fixed">
        <origin xyz="0 0.648335 0" rpy="0 0 1.5707963"/>
        <parent link="goalieRod2"/>
        <child link="goaliePlayer23"/>
    </joint>
    <joint name="DP11" type="fixed">
        <origin xyz="0 0.41021 0" rpy="0 0 1.5707963"/>
        <parent link="defenseRod1"/>
        <child link="defensePlayer11"/>
    </joint>
    <joint name="DP12" type="fixed">
        <origin xyz="0 0.65151 0" rpy="0 0 1.5707963"/>
        <parent link="defenseRod1"/>
        <child link="defensePlayer12"/>
    </joint>
    <joint name="DP21" type="fixed">
        <origin xyz="0 0.41021 0" rpy="0 0 1.5707963"/>
        <parent link="defenseRod2"/>
        <child link="defensePlayer21"/>
    </joint>
    <joint name="DP22" type="fixed">
        <origin xyz="0 0.65151 0" rpy="0 0 1.5707963"/>
        <parent link="defenseRod2"/>
        <child link="defensePlayer22"/>
    </joint>
    <joint name="MP11" type="fixed">
        <origin xyz="0 0.16891 0" rpy="0 0 1.5707963"/>
        <parent link="midfieldRod1"/>
        <child link="midfieldPlayer11"/>
    </joint>
    <joint name="MP12" type="fixed">
        <origin xyz="0 0.28956 0" rpy="0 0 1.5707963"/>
        <parent link="midfieldRod1"/>
        <child link="midfieldPlayer12"/>
    </joint>
    <joint name="MP13" type="fixed">
        <origin xyz="0 0.4191 0" rpy="0 0 1.5707963"/>
        <parent link="midfieldRod1"/>
        <child link="midfieldPlayer13"/>
    </joint>
    <joint name="MP14" type="fixed">
        <origin xyz="0 0.53086 0" rpy="0 0 1.5707963"/>
        <parent link="midfieldRod1"/>
        <child link="midfieldPlayer14"/>
    </joint>
    <joint name="MP15" type="fixed">
        <origin xyz="0 0.65151 0" rpy="0 0 1.5707963"/>
        <parent link="midfieldRod1"/>
        <child link="midfieldPlayer15"/>
    </joint>
    <joint name="MP21" type="fixed">
        <origin xyz="0 0.16891 0" rpy="0 0 1.5707963"/>
        <parent link="midfieldRod2"/>
        <child link="midfieldPlayer21"/>
    </joint>
    <joint name="MP22" type="fixed">
        <origin xyz="0 0.28956 0" rpy="0 0 1.5707963"/>
        <parent link="midfieldRod2"/>
        <child link="midfieldPlayer22"/>
    </joint>
    <joint name="MP23" type="fixed">
        <origin xyz="0 0.4191 0" rpy="0 0 1.5707963"/>
        <parent link="midfieldRod2"/>
        <child link="midfieldPlayer23"/>
    </joint>
    <joint name="MP24" type="fixed">
        <origin xyz="0 0.53086 0" rpy="0 0 1.5707963"/>
        <parent link="midfieldRod2"/>
        <child link="midfieldPlayer24"/>
    </joint>
    <joint name="MP25" type="fixed">
        <origin xyz="0 0.65151 0" rpy="0 0 1.5707963"/>
        <parent link="midfieldRod2"/>
        <child link="midfieldPlayer25"/>
    </joint>
    <joint name="SP11" type="fixed">
        <origin xyz="0 0.28321 0" rpy="0 0 1.5707963"/>
        <parent link="strikerRod1"/>
        <child link="strikerPlayer11"/>
    </joint>
    <joint name="SP12" type="fixed">
        <origin xyz="0 0.46736 0" rpy="0 0 1.5707963"/>
        <parent link="strikerRod1"/>
        <child link="strikerPlayer12"/>
    </joint>
    <joint name="SP13" type="fixed">
        <origin xyz="0 0.65151 0" rpy="0 0 1.5707963"/>
        <parent link="strikerRod1"/>
        <child link="strikerPlayer13"/>
    </joint>
    <joint name="SP21" type="fixed">
        <origin xyz="0 0.28321 0" rpy="0 0 1.5707963"/>
        <parent link="strikerRod2"/>
        <child link="strikerPlayer21"/>
    </joint>
    <joint name="SP22" type="fixed">
        <origin xyz="0 0.46736 0" rpy="0 0 1.5707963"/>
        <parent link="strikerRod2"/>
        <child link="strikerPlayer22"/>
    </joint>
    <joint name="SP23" type="fixed">
        <origin xyz="0 0.65151 0" rpy="0 0 1.5707963"/>
        <parent link="strikerRod2"/>
        <child link="strikerPlayer23"/>
    </joint>
</robot>
